<?xml version="1.0"?>
<robot name="cylbot">
  <link name="base_link">
    <visual>
      <geometry>
        <cylinder length="0.6" radius="0.2"/>
      </geometry>
      <material name="blue">
        <color rgba="0 0 .8 1"/>
      </material>
    </visual>
	<collision>
	  <geometry>
		<cylinder length="0.6" radius="0.2"/>
	  </geometry>
	</collision>
	<inertial>
	  <mass value="10"/>
	  <inertia ixx="0.4" ixy="0.0" ixz="0.0" iyy="0.4" iyz="0.0" izz="0.2"/>
	</inertial>
  </link>

  <link name="head_pole">
	<visual>
	  <geometry>
		<cylinder length=".2" radius=".02"/>
	  </geometry>
	  <material name="purple">
		<color rgba=".8 0 .8 1"/>
	  </material>
	</visual>
	<inertial>
	  <mass value=".1"/>
	  <inertia ixx="0.0004477824078" ixy="0.0" ixz="0.0" iyy="0.0004477824078" iyz="0.0" izz="0.0000066667356"/>
	</inertial>
  </link>

  <joint name="base_to_head_pole" type="fixed">
	<parent link="base_link"/>
	<child link="head_pole"/>
	<origin xyz="0 0 .4"/>
  </joint>

  <link name="right_wheel">
	<visual>
	  <geometry>
		<cylinder length=".05" radius=".2"/>
	  </geometry>
	  <material name="black">
		<color rgba="0 0 0 1"/>
	  </material>
	</visual>
	<collision>
	  <geometry>
		<cylinder length=".05" radius=".2"/>
	  </geometry>
	</collision>
	<inertial>
	  <mass value="1.5"/>
	  <inertia ixx=".01625" ixy="0.0" ixz="0.0" iyy=".01625" iyz="0.0" izz=".03"/>
	</inertial>
  </link>

  <joint name="right_wheel_joint" type="continuous">
	<parent link="base_link"/>
	<child link="right_wheel"/>
	<origin xyz=".23 0 -.2" rpy="0 1.57075 0"/>
	<axis xyz="0 0 1"/>
  </joint>

  <link name="left_wheel">
	<visual>
	  <geometry>
		<cylinder length=".05" radius=".2"/>
	  </geometry>
	  <material name="black">
		<color rgba="0 0 0 1"/>
	  </material>
	</visual>
	<collision>
	  <geometry>
		<cylinder length=".05" radius=".2"/>
	  </geometry>
	</collision>
	<inertial>
	  <mass value="1.5"/>
	  <inertia ixx=".01625" ixy="0.0" ixz="0.0" iyy=".01625" iyz="0.0" izz=".03"/>
	</inertial>
  </link>

  <joint name="left_wheel_joint" type="continuous">
	<parent link="base_link"/>
	<child link="left_wheel"/>
	<origin xyz="-.23 0 -.2" rpy="0 1.57075 0"/>
	<axis xyz="0 0 1"/>
  </joint>

  <link name="front_caster">
	<visual>
	  <geometry>
		<sphere radius=".075"/>
	  </geometry>
	  <material name="blue">
		<color rgba="0 0 .8 1"/>
	  </material>
	</visual>
	<collision>
	  <geometry>
		<sphere radius=".075"/>
	  </geometry>
	</collision>
  </link>

  <joint name="base_front_caster" type="fixed">
	<parent link="base_link"/>
	<child link="front_caster"/>
	<origin xyz="0 .125 -.325"/>
  </joint>

  <link name="back_caster">
	<visual>
	  <geometry>
		<sphere radius=".075"/>
	  </geometry>
	  <material name="blue">
		<color rgba="0 0 .8 1"/>
	  </material>
	</visual>
	<collision>
	  <geometry>
		<sphere radius=".075"/>
	  </geometry>
	</collision>
  </link>

  <joint name="base_back_caster" type="fixed">
	<parent link="base_link"/>
	<child link="back_caster"/>
	<origin xyz="0 -.125 -.325"/>
  </joint>

  <link name="head_tilt_link">
	<inertial>
	  <mass value=".01"/>
	  <inertia ixx="0.0004477824078" ixy="0.0" ixz="0.0" iyy="0.0004477824078" iyz="0.0" izz="0.0000066667356"/>
	</inertial>
  </link>

  <joint name="head_pan" type="continuous">
	<parent link="head_pole"/>
	<child link="head_tilt_link"/>
	<axis xyz="0 0 1"/>
	<origin xyz="0 0 .127" rpy="0 0 1.57075"/>
	<dynamics damping="0.7"/>
	<limit effort="10.0" velocity="5.0" />
  </joint>

  <joint name="head_tilt" type="continuous">
<<<<<<< Updated upstream
	<parent link="head_tilt_link"/>
=======
    <parent link="head_tilt_link"/>
    <child link="head_offset_link"/>
	<axis xyz="1 0 0"/>
    <origin xyz="0 0 0" rpy="0 0 0"/>
	<dynamics damping="0.7"/>
	<limit effort="10.0" velocity="5.0"/>
  </joint>

  <joint name="head_offset" type="fixed">
	<parent link="head_offset_link"/>
>>>>>>> Stashed changes
	<child link="head"/>
	<origin xyz="0 0 0" rpy="0 0 0"/>
	<axis xyz="0 1 0"/>
  </joint>

</robot>
